Workbook

Sheet سجل المصروفات التفصيلي
A1: هوستل الأهرامات — سجل كشف مصاريف الأستاذ خالد (المعدل والمعتمد بالكامل)
A2: تم التحديث والاعتماد المحاسبي بتاريخ: ١٠‏/٨‏/٢٠٢٦ — متوافق 100% مع التعديلات اليدوية المسجلة بالدفتر الشامل
A4: إجمالي المصروفات المعتمدة الكلية (بعد التعديلات اليدوية) | D4: إجمالي عدد البنود | F4: حالة اعتماد السجل
A5: =SUM(D8:D152) | D5: =COUNTA(C8:C152) | F5: معتمد 100%
A7: م | B7: مصدر المستند | C7: البيان وتفاصيل المصروف | D7: المبلغ (جنيه) | E7: حالة البند | F7: التصنيف الرئيسي | G7: ملاحظات وتوجيه محاسبي
A8: 1 | B8: صفحة 1 | C8: دفعة للعامل محمد زكي | D8: 10000 | E8: معتمد | F8: أجور وعمالة | G8: دفعة عامل
A9: 2 | B9: صفحة 1 | C9: دفعة من حساب إصلاح الكراسي | D9: 10000 | E9: معتمد | F9: أثاث ومفروشات | G9: إصلاح كراسي
A10: 3 | B10: صفحة 1 | C10: دفعة من حساب الأسانسير | D10: 10000 | E10: معتمد | F10: صيانة ومصاعد | G10: دفعة أسانسير
A11: 4 | B11: صفحة 1 | C11: دفعة عربون لمحمد السال المفروشات | D11: 10000 | E11: معتمد | F11: أثاث ومفروشات | G11: عربون مفروشات
A12: 5 | B12: صفحة 1 | C12: أكياس رايتس ثقيلة | D12: 300 | E12: معتمد | F12: نثريات وتجهيزات
A13: 6 | B13: صفحة 1 | C13: هناء (أجور وعمالة) | D13: 300 | E13: معتمد | F13: أجور وعمالة
A14: 7 | B14: صفحة 1 | C14: كرتونة مياه | D14: 250 | E14: معتمد | F14: نثريات وتجهيزات | G14: ضيافة وفندق
A15: 8 | B15: صفحة 1 | C15: نثريات ومصروفات عامة | D15: 350 | E15: معتمد | F15: نثريات وتجهيزات
A16: 9 | B16: صفحة 1 | C16: دفعة للولد البراويز | D16: 10000 | E16: معتمد | F16: أعمال تشطيب وديكور | G16: دفعة براويز
A17: 10 | B17: صفحة 1 | C17: سيارة نقل البراويز من الجيزة للفندق | D17: 500 | E17: معتمد | F17: نقل وشحن | G17: نقل ديكورات
A18: 11 | B18: صفحة 1 | C18: تكسير بار بالروف والمطبخ والحوائط | D18: 6000 | E18: معتمد | F18: أعمال مدنية ومباني | G18: تكسير وإزالة
A19: 12 | B19: صفحة 1 | C19: 10 أسمنت و 250 بلوك + 3 متر رملة وسن | D19: 4500 | E19: معتمد | F19: مواد بناء ومحارة | G19: أسمنت وبلوك ورمل وسن
A20: 13 | B20: صفحة 1 | C20: أجولة فارغة لتنزيل مخلفات الروف | D20: 300 | E20: معتمد | F20: نقل وشحن | G20: رفع مخلفات
A21: 14 | B21: صفحة 1 | C21: مقابض التواليت والكبائن والشبابيك | D21: 2150 | E21: معتمد | F21: إكسسوارات وتشطيبات | G21: مقابض وإكسسوار
A22: 15 | B22: صفحة 1 | C22: هناء | D22: 5000 | E22: معتمد | F22: أجور وعمالة | G22: أجور وإعاشة
A23: 16 | B23: صفحة 1 | C23: دفعة لعمرو المنجد من حساب ظهور السراير | D23: 2000 | E23: معتمد | F23: أثاث ومفروشات | G23: تنجيد ظهور سراير
A24: 17 | B24: صفحة 1 | C24: خالد المغربي (أجور ومصنوعيات) | D24: 2000 | E24: معتمد | F24: أجور وعمالة
A25: 18 | B25: صفحة 1 | C25: عربية نقل مخلفات من الريسبشن | D25: 500 | E25: معتمد | F25: نقل وشحن | G25: رفع مخلفات
A26: 19 | B26: صفحة 1 | C26: حساب الجبسين بورد روف + ريسبشن | D26: 23000 | E26: معتمد | F26: أعمال تشطيب وديكور | G26: جبس بورد للروف والريسبشن
A27: 20 | B27: صفحة 1 | C27: تكسير جدار الريسبشن (قطع حوائط) 250x28 | D27: 7000 | E27: معتمد | F27: أعمال مدنية ومباني | G27: تكسير حوائط
A28: 21 | B28: صفحة 1 | C28: 4 عمال لتطليع 450 متر سيراميك أرضيات وحوائط + أسمنت ورملة | D28: 1500 | E28: معتمد | F28: مواد بناء ومحارة | G28: تشوين وتطليع مواد وسيراميك
A29: 22 | B29: صفحة 1 | C29: أعمال تأسيس السباكة في الروف الحمامات الجديدة + الأبواب والمطبخ | D29: 3000 | E29: معتمد | F29: سباكة وصرف | G29: مصنعيات سباكة
A30: 23 | B30: صفحة 1 | C30: مشتروات السباكة للتأسيس | D30: 4500 | E30: معتمد | F30: سباكة وصرف | G30: خامات سباكة تأسيس
A31: 24 | B31: صفحة 1 | C31: استكمال مشتروات السباكة | D31: 460 | E31: معتمد | F31: سباكة وصرف | G31: خامات سباكة
A32: 25 | B32: صفحة 1 | C32: فاتورة غسيل الفرش القديم | D32: 2240 | E32: معتمد | F32: مرافق وفواتير | G32: غسيل مفارش وفرش
A33: 26 | B33: صفحة 1 | C33: عدد 4 عمال لتنظيف الروف والأدوار والسلم والريسبشن | D33: 1600 | E33: معتمد | F33: أجور وعمالة | G33: عمال نظافة
A34: 27 | B34: صفحة 1 | C34: جالون لاكية أسود للمحلات | D34: 380 | E34: معتمد | F34: دهانات وتكسية | G34: دهانات لاكيه
A35: 28 | B35: صفحة 1 | C35: فاتورة كهرباء شهر (5) | D35: 6050 | E35: معتمد | F35: كهرباء وإنارة | G35: كهرباء شهر مايو
A36: 29 | B36: صفحة 1 | C36: مناولة لمحمد زكي لتفضيل أعماله بحضور أحمد العليان | D36: 5000 | E36: معتمد | F36: أجور وعمالة | G36: مناولة أعمال
... A41: 34 | B41: صفحة 2 | C41: نقل أدوات السباكة | D41: 300 | E41: معتمد | F41: سباكة وصرف | G41: نقل خامات
A42: 35 | B42: صفحة 2 | C42: الرشاطة + كيس فلق الأسانسير | D42: 300 | E42: معتمد | F42: صيانة ومصاعد
A43: 36 | B43: صفحة 2 | C43: جركن أدي بوند + شكارة مادة | D43: 500 | E43: معتمد | F43: مواد بناء ومحارة
A44: 37 | B44: صفحة 2 | C44: أجولة فارغة | D44: 100 | E44: معتمد | F44: نثريات وتجهيزات
A45: 38 | B45: صفحة 2 | C45: أحمد العليان أختام | D45: 1600 | E45: معتمد | F45: أجور وعمالة | G45: أختام وأعمال
A46: 39 | B46: صفحة 2 | C46: شركة الرضا صيانات + حامل تكييف + حامل فوط | D46: 9300 | E46: معتمد | F46: صيانة ومصاعد | G46: صيانات وإكسسوار تكييفات
...

Sheet ملخص حسب التصنيفات
A1: هوستل الأهرامات — ملخص المصروفات المعدلة موزع حسب التصنيفات الرئيسية
A3: التصنيف المحاسبي الرئيسي | B3: إجمالي المصروفات المعتمدة (جنيه) | C3: عدد البنود المعتمدة | D3: النسبة المئوية من الإجمالي
A4: أجور وعمالة | B4: =SUMIF('سجل المصروفات التفصيلي'!F8:F152, "أجور وعمالة", 'سجل المصروفات التفصيلي'!D8:D152) | C4: =COUNTIF('سجل المصروفات التفصيلي'!F8:F152, "أجور وعمالة") | D4: =B4/B19
A5: أثاث ومفروشات | B5: =SUMIF('سجل المصروفات التفصيلي'!F8:F152, "أثاث ومفروشات", 'سجل المصروفات التفصيلي'!D8:D152) | C5: =COUNTIF('سجل المصروفات التفصيلي'!F8:F152, "أثاث ومفروشات") | D5: =B5/B19
A6: صيانة ومصاعد | B6: =SUMIF('سجل المصروفات التفصيلي'!F8:F152, "صيانة ومصاعد", 'سجل المصروفات التفصيلي'!D8:D152) | C6: =COUNTIF('سجل المصروفات التفصيلي'!F8:F152, "صيانة ومصاعد") | D6: =B6/B19
A7: نثريات وتجهيزات | B7: =SUMIF('سجل المصروفات التفصيلي'!F8:F152, "نثريات وتجهيزات", 'سجل المصروفات التفصيلي'!D8:D152) | C7: =COUNTIF('سجل المصروفات التفصيلي'!F8:F152, "نثريات وتجهيزات") | D7: =B7/B19
A8: أعمال تشطيب وديكور | B8: =SUMIF('سجل المصروفات التفصيلي'!F8:F152, "أعمال تشطيب وديكور", 'سجل المصروفات التفصيلي'!D8:D152) | C8: =COUNTIF('سجل المصروفات التفصيلي'!F8:F152, "أعمال تشطيب وديكور") | D8: =B8/B19
A9: نقل وشحن | B9: =SUMIF('سجل المصروفات التفصيلي'!F8:F152, "نقل وشحن", 'سجل المصروفات التفصيلي'!D8:D152) | C9: =COUNTIF('سجل المصروفات التفصيلي'!F8:F152, "نقل وشحن") | D9: =B9/B19
A10: أعمال مدنية ومباني | B10: =SUMIF('سجل المصروفات التفصيلي'!F8:F152, "أعمال مدنية ومباني", 'سجل المصروفات التفصيلي'!D8:D152) | C10: =COUNTIF('سجل المصروفات التفصيلي'!F8:F152, "أعمال مدنية ومباني") | D10: =B10/B19
A11: مواد بناء ومحارة | B11: =SUMIF('سجل المصروفات التفصيلي'!F8:F152, "مواد بناء ومحارة", 'سجل المصروفات التفصيلي'!D8:D152) | C11: =COUNTIF('سجل المصروفات التفصيلي'!F8:F152, "مواد بناء ومحارة") | D11: =B11/B19
A12: إكسسوارات وتشطيبات | B12: =SUMIF('سجل المصروفات التفصيلي'!F8:F152, "إكسسوارات وتشطيبات", 'سجل المصروفات التفصيلي'!D8:D152) | C12: =COUNTIF('سجل المصروفات التفصيلي'!F8:F152, "إكسسوارات وتشطيبات") | D12: =B12/B19
A13: سباكة وصرف | B13: =SUMIF('سجل المصروفات التفصيلي'!F8:F152, "سباكة وصرف", 'سجل المصروفات التفصيلي'!D8:D152) | C13: =COUNTIF('سجل المصروفات التفصيلي'!F8:F152, "سباكة وصرف") | D13: =B13/B19
A14: مرافق وفواتير | B14: =SUMIF('سجل المصروفات التفصيلي'!F8:F152, "مرافق وفواتير", 'سجل المصروفات التفصيلي'!D8:D152) | C14: =COUNTIF('سجل المصروفات التفصيلي'!F8:F152, "مرافق وفواتير") | D14: =B14/B19
A15: دهانات وتكسية | B15: =SUMIF('سجل المصروفات التفصيلي'!F8:F152, "دهانات وتكسية", 'سجل المصروفات التفصيلي'!D8:D152) | C15: =COUNTIF('سجل المصروفات التفصيلي'!F8:F152, "دهانات وتكسية") | D15: =B15/B19
A16: كهرباء وإنارة | B16: =SUMIF('سجل المصروفات التفصيلي'!F8:F152, "كهرباء وإنارة", 'سجل المصروفات التفصيلي'!D8:D152) | C16: =COUNTIF('سجل المصروفات التفصيلي'!F8:F152, "كهرباء وإنارة") | D16: =B16/B19
A17: نظافة وغسيل | B17: =SUMIF('سجل المصروفات التفصيلي'!F8:F152, "نظافة وغسيل", 'سجل المصروفات التفصيلي'!D8:D152) | C17: =COUNTIF('سجل المصروفات التفصيلي'!F8:F152, "نظافة وغسيل") | D17: =B17/B19
A18: ديكور ومكملات | B18: =SUMIF('سجل المصروفات التفصيلي'!F8:F152, "ديكور ومكملات", 'سجل المصروفات التفصيلي'!D8:D152) | C18: =COUNTIF('سجل المصروفات التفصيلي'!F8:F152, "ديكور ومكملات") | D18: =B18/B19
A19: المجموع الإجمالي | B19: =SUM(B4:B18) | C19: =SUM(C4:C18) | D19: =SUM(D4:D18)

Sheet مطابقة صفحات الدفتر
A1: هوستل الأهرامات — جدول مطابقة صفحات الدفتر الورقي (بعد التعديلات اليدوية)
A3: رقم الصفحة / المستند | B3: إجمالي الصفحة المحسوب بالإكسيل (جنيه) | C3: عدد البنود بالصفحة | D3: ملاحظات المطابقة المحاسبية
A4: صفحة 1 | B4: =SUMIF('سجل المصروفات التفصيلي'!B8:B152, "صفحة 1", 'سجل المصروفات التفصيلي'!D8:D152) | C4: =COUNTIF('سجل المصروفات التفصيلي'!B8:B152, "صفحة 1") | D4: مطابق للقيم والبنود المعدلة بدفتر المصروفات
A5: صفحة 2 | B5: =SUMIF('سجل المصروفات التفصيلي'!B8:B152, "صفحة 2", 'سجل المصروفات التفصيلي'!D8:D152) | C5: =COUNTIF('سجل المصروفات التفصيلي'!B8:B152, "صفحة 2") | D5: مطابق للقيم والبنود المعدلة بدفتر المصروفات
A6: صفحة 3 | B6: =SUMIF('سجل المصروفات التفصيلي'!B8:B152, "صفحة 3", 'سجل المصروفات التفصيلي'!D8:D152) | C6: =COUNTIF('سجل المصروفات التفصيلي'!B8:B152, "صفحة 3") | D6: مطابق للقيم والبنود المعدلة بدفتر المصروفات
A7: صفحة 4 | B7: =SUMIF('سجل المصروفات التفصيلي'!B8:B152, "صفحة 4", 'سجل المصروفات التفصيلي'!D8:D152) | C7: =COUNTIF('سجل المصروفات التفصيلي'!B8:B152, "صفحة 4") | D7: مطابق للقيم والبنود المعدلة بدفتر المصروفات
A8: صفحة 5 | B8: =SUMIF('سجل المصروفات التفصيلي'!B8:B152, "صفحة 5", 'سجل المصروفات التفصيلي'!D8:D152) | C8: =COUNTIF('سجل المصروفات التفصيلي'!B8:B152, "صفحة 5") | D8: مطابق للقيم والبنود المعدلة بدفتر المصروفات
A9: صفحة 6 (ملاحظة 10 أغسطس) | B9: =SUMIF('سجل المصروفات التفصيلي'!B8:B152, "صفحة 6 (ملاحظة 10 أغسطس)", 'سجل المصروفات التفصيلي'!D8:D152) | C9: =COUNTIF('سجل المصروفات التفصيلي'!B8:B152, "صفحة 6 (ملاحظة 10 أغسطس)") | D9: مطابق للقيم والبنود المعدلة بدفتر المصروفات
A10: المجموع الإجمالي الشامل | B10: =SUM(B4:B9) | C10: =SUM(C4:C9) | D10: إجمالي كافة الصفحات والمستندات معتمدة 100%
